<?xml version="1.0" ?>
<!-- =================================================================================== -->
<!-- |    This document was autogenerated by xacro from dokalman_description.xacro     | -->
<!-- |    EDITING THIS FILE BY HAND IS NOT RECOMMENDED                                 | -->
<!-- =================================================================================== -->
<robot name="dokalman">
  <!-- Robot Base -->
  <link name="base_link">
    <inertial>
      <origin rpy="0 0 0" xyz="0 0 0"/>
      <mass value="8"/>
      <inertia ixx="0.56" ixy="0" ixz="0" iyy="0.38" iyz="0" izz="0.21"/>
    </inertial>
    <visual>
      <origin rpy="0 0 1.5708" xyz="0 0 0"/>
      <!-- 1.5708 radians = 90 degrees -->
      <geometry>
        <mesh filename="package://dokalman/meshes/base_link.STL"/>
      </geometry>
      <material name="Gray">
        <color rgba="0.5 0.5 0.5 1.0"/>
      </material>
    </visual>
  </link>
  <!-- Robot Footprint -->
  <link name="base_footprint"/>
  <joint name="base_joint" type="fixed">
    <parent link="base_link"/>
    <child link="base_footprint"/>
    <origin rpy="0 0 0" xyz="0.0 0.0 -0.155"/>
  </joint>
  <link name="drivewhl_l_link">
    <inertial>
      <origin rpy="0 0 0" xyz="0 0 0"/>
      <mass value="1"/>
      <inertia ixx="0.0008" ixy="0" ixz="0" iyy="0.0008" iyz="0" izz="0.00015"/>
    </inertial>
    <visual>
      <origin rpy="1.5707963267948966 0 0" xyz="0 0 0"/>
      <geometry>
        <cylinder length="0.04" radius="0.155"/>
      </geometry>
      <material name="Gray">
        <color rgba="0.5 0.5 0.5 1.0"/>
      </material>
    </visual>
  </link>
  <joint name="drivewhl_l_joint" type="continuous">
    <parent link="base_link"/>
    <child link="drivewhl_l_link"/>
    <origin rpy="0 0 0" xyz="-0.0 0.265 -0.0"/>
    <axis xyz="0 1 0"/>
  </joint>
  <link name="drivewhl_r_link">
    <inertial>
      <origin rpy="0 0 0" xyz="0 0 0"/>
      <mass value="1"/>
      <inertia ixx="0.0008" ixy="0" ixz="0" iyy="0.0008" iyz="0" izz="0.00015"/>
    </inertial>
    <visual>
      <origin rpy="1.5707963267948966 0 0" xyz="0 0 0"/>
      <geometry>
        <cylinder length="0.04" radius="0.155"/>
      </geometry>
      <material name="Gray">
        <color rgba="0.5 0.5 0.5 1.0"/>
      </material>
    </visual>
  </link>
  <joint name="drivewhl_r_joint" type="continuous">
    <parent link="base_link"/>
    <child link="drivewhl_r_link"/>
    <origin rpy="0 0 0" xyz="-0.0 -0.265 -0.0"/>
    <axis xyz="0 1 0"/>
  </joint>
  <!-- Caster Wheel -->
  <link name="front_caster">
    <inertial>
      <origin rpy="0 0 0" xyz="0 0 0"/>
      <mass value="0.5"/>
      <inertia ixx="0.0001" ixy="0" ixz="0" iyy="0.0001" iyz="0" izz="0.0002"/>
    </inertial>
    <visual>
      <origin rpy="1.5708 0 1.5708" xyz="-0.05 0 -0.16"/>
      <!-- 1.5708 radians = 90 degrees -->
      <geometry>
        <mesh filename="package://dokalman/meshes/Caster.STL"/>
      </geometry>
      <material name="Gray">
        <color rgba="0 1.0 1.0 1.0"/>
      </material>
    </visual>
  </link>
  <joint name="caster_joint" type="fixed">
    <parent link="base_link"/>
    <child link="front_caster"/>
    <origin rpy="0 0 0" xyz="0.5 0.0 0"/>
  </joint>
  <!-- GPS -->
  <link name="back_gps">
    <inertial>
      <origin rpy="0 0 0" xyz="0 0 0"/>
      <mass value="0.1"/>
      <inertia ixx="0.000001" ixy="0" ixz="0" iyy="0.000001" iyz="0" izz="0.000002"/>
    </inertial>
    <visual>
      <origin rpy="1.5708 0 1.5708" xyz="-0.025 0.025 0"/>
      <!-- 1.5708 radians = 90 degrees -->
      <geometry>
        <mesh filename="package://dokalman/meshes/FrontGPS.STL"/>
      </geometry>
      <material name="Gray">
        <color rgba="0 1.0 1.0 1.0"/>
      </material>
    </visual>
  </link>
  <joint name="back_gps_joint" type="fixed">
    <parent link="base_link"/>
    <child link="back_gps"/>
    <origin rpy="0 0 0" xyz="0.0 0.0 0.465"/>
  </joint>
  <link name="front_gps">
    <inertial>
      <origin rpy="0 0 0" xyz="0 0 0"/>
      <mass value="0.1"/>
      <inertia ixx="0.000001" ixy="0" ixz="0" iyy="0.000001" iyz="0" izz="0.000002"/>
    </inertial>
    <visual>
      <origin rpy="1.5708 0 -1.5708" xyz="0.025 -0.025 0"/>
      <!-- 1.5708 radians = 90 degrees -->
      <geometry>
        <mesh filename="package://dokalman/meshes/BackGPS.STL"/>
      </geometry>
      <material name="Gray">
        <color rgba="0 1.0 1.0 1.0"/>
      </material>
    </visual>
  </link>
  <joint name="front_gps_joint" type="fixed">
    <parent link="base_link"/>
    <child link="front_gps"/>
    <origin rpy="0 0 0" xyz="0.6 0.0 0.465"/>
  </joint>
  <!-- CAMERAS -->
  <link name="left_cam">
    <inertial>
      <origin rpy="0 0 0" xyz="0 0 0"/>
      <mass value="0.2"/>
      <inertia ixx="0.000005" ixy="0" ixz="0" iyy="0.000005" iyz="0" izz="0.00001"/>
    </inertial>
    <visual>
      <origin rpy="1.5708 0 1.5708" xyz="0.01 0.02 0.025"/>
      <!-- 1.5708 radians = 90 degrees -->
      <geometry>
        <mesh filename="package://dokalman/meshes/FLCam.STL"/>
      </geometry>
      <material name="Gray">
        <color rgba="0 1.0 1.0 1.0"/>
      </material>
    </visual>
  </link>
  <joint name="left_cam_joint" type="fixed">
    <parent link="base_link"/>
    <child link="left_cam"/>
    <origin rpy="0 0 -1" xyz="0.5 -0.16 0.465"/>
  </joint>
  <link name="right_cam">
    <inertial>
      <origin rpy="0 0 0" xyz="0 0 0"/>
      <mass value="0.2"/>
      <inertia ixx="0.000005" ixy="0" ixz="0" iyy="0.000005" iyz="0" izz="0.00001"/>
    </inertial>
    <visual>
      <origin rpy="1.5708 0 1.5708" xyz="0.01 0.02 0.025"/>
      <!-- 1.5708 radians = 90 degrees -->
      <geometry>
        <mesh filename="package://dokalman/meshes/FRCam.STL"/>
      </geometry>
      <material name="Gray">
        <color rgba="0 1.0 1.0 1.0"/>
      </material>
    </visual>
  </link>
  <joint name="right_cam_joint" type="fixed">
    <parent link="base_link"/>
    <child link="right_cam"/>
    <origin rpy="0 0 1" xyz="0.5 0.16 0.465"/>
  </joint>
</robot>
