<sdf version='1.7'>
  <model name='dokalman'>
    <link name='base_link'>
      <inertial>
        <pose>0.056044 0 0.030659 0 -0 0</pose>
        <mass>9.1</mass>
        <inertia>
          <ixx>0.691533</ixx>
          <ixy>0</ixy>
          <ixz>-0.105264</ixz>
          <iyy>0.733711</iyy>
          <iyz>0</iyz>
          <izz>0.452882</izz>
        </inertia>
      </inertial>
      <visual name='base_link_visual'>
        <pose>0 0 0 0 -0 1.5708</pose>
        <geometry>
          <mesh>
            <scale>1 1 1</scale>
            <uri>model://dokalman/meshes/base_link.STL</uri>
          </mesh>
        </geometry>
      </visual>
      <visual name='base_link_fixed_joint_lump__back_gps_visual_1'>
        <pose>-0.025 0.025 0.465 1.5708 -0 1.5708</pose>
        <geometry>
          <mesh>
            <scale>1 1 1</scale>
            <uri>model://dokalman/meshes/FrontGPS.STL</uri>
          </mesh>
        </geometry>
      </visual>
      <visual name='base_link_fixed_joint_lump__front_caster_visual_2'>
        <pose>0.45 0 -0.16 1.5708 -0 1.5708</pose>
        <geometry>
          <mesh>
            <scale>1 1 1</scale>
            <uri>model://dokalman/meshes/Caster.STL</uri>
          </mesh>
        </geometry>
      </visual>
      <visual name='base_link_fixed_joint_lump__front_gps_visual_3'>
        <pose>0.625 -0.025 0.465 1.5708 0 -1.5708</pose>
        <geometry>
          <mesh>
            <scale>1 1 1</scale>
            <uri>model://dokalman/meshes/BackGPS.STL</uri>
          </mesh>
        </geometry>
      </visual>
      <visual name='base_link_fixed_joint_lump__left_cam_visual_4'>
        <pose>0.522232 -0.157609 0.49 1.5708 -0 0.5708</pose>
        <geometry>
          <mesh>
            <scale>1 1 1</scale>
            <uri>model://dokalman/meshes/FLCam.STL</uri>
          </mesh>
        </geometry>
      </visual>
      <visual name='base_link_fixed_joint_lump__right_cam_visual_5'>
        <pose>0.488574 0.179221 0.49 1.5708 -0 2.5708</pose>
        <geometry>
          <mesh>
            <scale>1 1 1</scale>
            <uri>model://dokalman/meshes/FRCam.STL</uri>
          </mesh>
        </geometry>
      </visual>
    </link>
    <joint name='drivewhl_l_joint' type='revolute'>
      <pose relative_to='base_link'>0 0.265 0 0 -0 0</pose>
      <parent>base_link</parent>
      <child>drivewhl_l_link</child>
      <axis>
        <xyz>0 1 0</xyz>
        <limit>
          <lower>-1e+16</lower>
          <upper>1e+16</upper>
        </limit>
        <dynamics>
          <spring_reference>0</spring_reference>
          <spring_stiffness>0</spring_stiffness>
        </dynamics>
      </axis>
    </joint>
    <link name='drivewhl_l_link'>
      <pose relative_to='drivewhl_l_joint'>0 0 0 0 -0 0</pose>
      <inertial>
        <pose>0 0 0 0 -0 0</pose>
        <mass>1</mass>
        <inertia>
          <ixx>0.0008</ixx>
          <ixy>0</ixy>
          <ixz>0</ixz>
          <iyy>0.0008</iyy>
          <iyz>0</iyz>
          <izz>0.00015</izz>
        </inertia>
      </inertial>
      <visual name='drivewhl_l_link_visual'>
        <pose>0 0 0 1.5708 -0 0</pose>
        <geometry>
          <cylinder>
            <length>0.04</length>
            <radius>0.155</radius>
          </cylinder>
        </geometry>
      </visual>
    </link>
    <joint name='drivewhl_r_joint' type='revolute'>
      <pose relative_to='base_link'>0 -0.265 0 0 -0 0</pose>
      <parent>base_link</parent>
      <child>drivewhl_r_link</child>
      <axis>
        <xyz>0 1 0</xyz>
        <limit>
          <lower>-1e+16</lower>
          <upper>1e+16</upper>
        </limit>
        <dynamics>
          <spring_reference>0</spring_reference>
          <spring_stiffness>0</spring_stiffness>
        </dynamics>
      </axis>
    </joint>
    <link name='drivewhl_r_link'>
      <pose relative_to='drivewhl_r_joint'>0 0 0 0 -0 0</pose>
      <inertial>
        <pose>0 0 0 0 -0 0</pose>
        <mass>1</mass>
        <inertia>
          <ixx>0.0008</ixx>
          <ixy>0</ixy>
          <ixz>0</ixz>
          <iyy>0.0008</iyy>
          <iyz>0</iyz>
          <izz>0.00015</izz>
        </inertia>
      </inertial>
      <visual name='drivewhl_r_link_visual'>
        <pose>0 0 0 1.5708 -0 0</pose>
        <geometry>
          <cylinder>
            <length>0.04</length>
            <radius>0.155</radius>
          </cylinder>
        </geometry>
      </visual>
    </link>
  </model>
</sdf>
